Traceback (most recent call last):
  File "/home/runner/.local/lib/python3.10/site-packages/jupyter_cache/executors/utils.py", line 58, in single_nb_execution
    executenb(
  File "/home/runner/.local/lib/python3.10/site-packages/nbclient/client.py", line 1305, in execute
    return NotebookClient(nb=nb, resources=resources, km=km, **kwargs).execute()
  File "/home/runner/.local/lib/python3.10/site-packages/jupyter_core/utils/__init__.py", line 165, in wrapped
    return loop.run_until_complete(inner)
  File "/usr/lib/python3.10/asyncio/base_events.py", line 649, in run_until_complete
    return future.result()
  File "/home/runner/.local/lib/python3.10/site-packages/nbclient/client.py", line 705, in async_execute
    await self.async_execute_cell(
  File "/home/runner/.local/lib/python3.10/site-packages/nbclient/client.py", line 1058, in async_execute_cell
    await self._check_raise_for_error(cell, cell_index, exec_reply)
  File "/home/runner/.local/lib/python3.10/site-packages/nbclient/client.py", line 914, in _check_raise_for_error
    raise CellExecutionError.from_cell_and_msg(cell, exec_reply_content)
nbclient.exceptions.CellExecutionError: An error occurred while executing the following cell:
------------------
from sklearn.ensemble import RandomForestClassifier
from sklearn.datasets import load_iris
from sklearn.model_selection import train_test_split
from sklearn.tree import export_graphviz
import pydotplus
import matplotlib.pyplot as plt

# Âä†ËΩΩÊï∞ÊçÆ
data = load_iris()
X = data.data
y = data.target

# ÂàíÂàÜËÆ≠ÁªÉÈõÜÂíåÊµãËØïÈõÜ
X_train, X_test, y_train, _ = train_test_split(X, y, test_size=0.2, random_state=42)

# ÂàõÂª∫ÈöèÊú∫Ê£ÆÊûóÂàÜÁ±ªÂô®
model = RandomForestClassifier()

# ËÆ≠ÁªÉÊ®°Âûã
model.fit(X_train, y_train)

# ÂèØËßÜÂåñÂÜ≥Á≠ñÊ†ëÔºàÁ¨¨‰∏ÄÊ£µÊ†ëÔºâ
estimator = model.estimators_[0]
dot_data = export_graphviz(estimator, out_file=None, feature_names=data.feature_names,
                           class_names=data.target_names, filled=True, rounded=True)
graph = pydotplus.graph_from_dot_data(dot_data)

# ‰øùÂ≠ò‰∏∫ÂõæÂÉèÊñá‰ª∂
graph.write_png('random_forest_tree.png')

# ‰ΩøÁî®matplotlibÊòæÁ§∫ÂõæÂÉè
plt.figure(figsize=(10, 10))
plt.imshow(plt.imread('random_forest_tree.png'))
plt.axis('off')
plt.show()
------------------


[0;31m---------------------------------------------------------------------------[0m
[0;31mModuleNotFoundError[0m                       Traceback (most recent call last)
Cell [0;32mIn[1], line 5[0m
[1;32m      3[0m [38;5;28;01mfrom[39;00m [38;5;21;01msklearn[39;00m[38;5;21;01m.[39;00m[38;5;21;01mmodel_selection[39;00m [38;5;28;01mimport[39;00m train_test_split
[1;32m      4[0m [38;5;28;01mfrom[39;00m [38;5;21;01msklearn[39;00m[38;5;21;01m.[39;00m[38;5;21;01mtree[39;00m [38;5;28;01mimport[39;00m export_graphviz
[0;32m----> 5[0m [38;5;28;01mimport[39;00m [38;5;21;01mpydotplus[39;00m
[1;32m      6[0m [38;5;28;01mimport[39;00m [38;5;21;01mmatplotlib[39;00m[38;5;21;01m.[39;00m[38;5;21;01mpyplot[39;00m [38;5;28;01mas[39;00m [38;5;21;01mplt[39;00m
[1;32m      8[0m [38;5;66;03m# Âä†ËΩΩÊï∞ÊçÆ[39;00m

[0;31mModuleNotFoundError[0m: No module named 'pydotplus'

